<mujoco model="humanoid">
    <compiler angle="degree" inertiafromgeom="true"/>
    <default>
        <joint armature="1" damping="1" limited="true"/>
        <geom conaffinity="0" condim="3" contype="0" material="geom" rgba="0.4 0.33 0.26 1.0"/>
        <position kp="21.1" ctrlrange="-3.141592 3.141592"/>
    </default>
    <option iterations="8" timestep="0.003"/>
    <custom>
        <!-- brax custom params -->
        <numeric data="2500" name="constraint_limit_stiffness"/>
        <numeric data="27000" name="constraint_stiffness"/>
        <numeric data="30" name="constraint_ang_damping"/>
        <numeric data="80" name="constraint_vel_damping"/>
        <numeric data="-0.05" name="ang_damping"/>
        <numeric data="0.5" name="joint_scale_pos"/>
        <numeric data="0.1" name="joint_scale_ang"/>
        <numeric data="0" name="spring_mass_scale"/>
        <numeric data="1" name="spring_inertia_scale"/>
        <numeric data="20" name="matrix_inv_iterations"/>
        <numeric data="15" name="solver_maxls"/>
    </custom>
    <size nkey="5" nuser_geom="1"/>
    <visual>
        <map fogend="5" fogstart="3"/>
    </visual>
    <asset>
        <texture builtin="gradient" height="100" rgb1=".4 .5 .6" rgb2="0 0 0" type="skybox" width="100"/>
        <texture builtin="flat" height="1278" mark="cross" markrgb="1 1 1" name="texgeom" random="0.01" rgb1="0.8 0.6 0.4" rgb2="0.8 0.6 0.4" type="cube" width="127"/>
        <texture builtin="checker" height="100" name="texplane" rgb1="0 0 0" rgb2="0.8 0.8 0.8" type="2d" width="100"/>
        <material name="MatPlane" reflectance="0.5" shininess="1" specular="1" texrepeat="60 60" texture="texplane"/>
        <material name="geom" texture="texgeom" texuniform="true"/>
    </asset>
    <worldbody>
        <light cutoff="100" diffuse="1 1 1" dir="-0 0 -1.3" directional="true" exponent="1" pos="0 0 1.3" specular=".1 .1 .1"/>
        <geom conaffinity="1" condim="3" friction="1 .1 .1" material="MatPlane" name="floor" pos="0 0 0" size="20 20 0.125" type="plane" rgba="0.5 0.5 0.5 1.0"/>
        <body name="torso" pos="0 0 0.5">
            <site name="imu"/>
            <camera name="track" mode="trackcom" pos="0 -4 0" xyaxes="1 0 0 0 0 1"/>
            <joint armature="0" damping="0" limited="false" name="root" pos="0 0 0" stiffness="0" type="free"/>
            <geom contype="1" fromto="0 0 -0.125 0 0 0.125" name="torso1" size="0.07" type="box"/>
            <geom contype="1" name="head" pos="0 0 .19" size=".07" type="sphere" user="258"/>
            <!-- Right Thigh - Directly connected to torso -->
            <body name="right_thigh" pos="0 -0.13 -0.125">
                <joint armature="0.01" axis="1 0 0" damping="5" name="right_hip_x" pos="0 0 0" range="-25 5" stiffness="10" type="hinge"/>
                <joint armature="0.01" axis="0 0 1" damping="5" name="right_hip_z" pos="0 0 0" range="-35 35" stiffness="10" type="hinge"/>
                <joint armature="0.0080" axis="0 1 0" damping="5" name="right_hip_y" pos="0 0 0" range="-90 60" stiffness="10" type="hinge"/>
                <geom contype="1" fromto="0 0 0.081 0 0.01 -.121" name="right_thigh1" size="0.06" type="box"/>
                <body name="right_shin" pos="0 0.01 -0.121">
                    <joint armature="0.0060" axis="0 -1 0" name="right_knee" pos="0 0 .02" range="-90 0" type="hinge"/>
                    <geom contype="1" fromto="0 0 0 0 0 -.202" name="right_shin1" size="0.049" type="box"/>
                    <body name="right_foot" pos="0 0 -0.102">
                        <site name="right_foot"/>
                        <joint armature="0.01" axis="0 -1 0" damping="5" name="right_foot" pos="0 0 0" range="-25 25" stiffness="10" type="hinge"/>
                        <geom contype="1" name="right_foot" pos="0 0 -0.102" size="0.075 0.05 0.025" type="box" user="0"/>
                    </body>
                </body>
            </body>
            <!-- Left Thigh - Directly connected to torso -->
            <body name="left_thigh" pos="0 0.13 -0.125">
                <joint armature="0.01" axis="-1 0 0" damping="5" name="left_hip_x" pos="0 0 0" range="-25 5" stiffness="10" type="hinge"/>
                <joint armature="0.01" axis="0 0 -1" damping="5" name="left_hip_z" pos="0 0 0" range="-35 35" stiffness="10" type="hinge"/>
                <joint armature="0.01" axis="0 1 0" damping="5" name="left_hip_y" pos="0 0 0" range="-90 60" stiffness="10" type="hinge"/>
                <geom contype="1" fromto="0 0 0.081 0 0.01 -.121" name="left_thigh1" size="0.06" type="box"/>
                <body name="left_shin" pos="0 -0.01 -0.121">
                    <joint armature="0.0060" axis="0 -1 0" name="left_knee" pos="0 0 .02" range="-90 0" stiffness="10" type="hinge"/>
                    <geom contype="1" fromto="0 0 0 0 0 -.202" name="left_shin1" size="0.049" type="box"/>
                    <body name="left_foot" pos="0 0 -0.102">
                        <site name="left_foot"/>
                        <joint armature="0.01" axis="0 -1 0" damping="5" name="left_foot" pos="0 0 0" range="-25 25" stiffness="10" type="hinge"/>
                        <geom contype="1" name="left_foot" pos="0 0 -0.102" size="0.075 0.05 0.025" type="box" user="0"/>
                    </body>
                </body>
            </body>
            <body name="right_upper_arm" pos="0 -0.17 0.06">
                <joint armature="0.0068" axis="2 1 1" name="right_shoulder1" pos="0 0 0" range="-85 40" stiffness="10" type="hinge"/>
                <joint armature="0.0051" axis="0 -1 1" name="right_shoulder2" pos="0 0 0" range="-85 40" stiffness="10" type="hinge"/>
                <geom fromto="0 0 0 .122 -.122 -.122" name="right_uarm1" size="0.04 0.16" type="box"/>
                <body name="right_lower_arm" pos=".122 -.122 -.122">
                    <joint armature="0.0028" axis="0 -1 1" name="right_elbow" pos="0 0 0" range="-90 50" stiffness="10" type="hinge"/>
                    <geom contype="1" fromto="0 0 0 .075 .075 .075" name="right_larm" size="0.031" type="box"/>
                    <geom contype="1" name="right_hand" pos=".075 .075 .075" size="0.04" type="sphere"/>
                </body>
            </body>
            <body name="left_upper_arm" pos="0 0.17 0.06">
                <joint armature="0.0068" axis="2 -1 1" name="left_shoulder1" pos="0 0 0" range="-40 85" stiffness="10" type="hinge"/>
                <joint armature="0.0051" axis="0 1 1" name="left_shoulder2" pos="0 0 0" range="-40 85" stiffness="10" type="hinge"/>
                <geom contype="1" fromto="0 0 0 .122 .122 -.122" name="left_uarm1" size="0.04 0.16" type="box"/>
                <body name="left_lower_arm" pos=".122 .122 -.122">
                    <joint armature="0.0028" axis="0 -1 -1" name="left_elbow" pos="0 0 0" range="-90 50" stiffness="10" type="hinge"/>
                    <geom contype="1" fromto="0 0 0 .075 -.075 .075" name="left_larm" size="0.031" type="box"/>
                    <geom contype="1" name="left_hand" pos=".075 -.075 .075" size="0.04" type="sphere"/>
                </body>
            </body>
        </body>
    </worldbody>
    <actuator>
        <position joint="right_hip_x" name="right_hip_x"/>
        <position joint="right_hip_z" name="right_hip_z"/>
        <position joint="right_hip_y" name="right_hip_y"/>
        <position joint="right_knee" name="right_knee"/>
        <position joint="left_hip_x" name="left_hip_x"/>
        <position joint="left_hip_z" name="left_hip_z"/>
        <position joint="left_hip_y" name="left_hip_y"/>
        <position joint="left_knee" name="left_knee"/>
        <position joint="right_shoulder1" name="right_shoulder1"/>
        <position joint="right_shoulder2" name="right_shoulder2"/>
        <position joint="right_elbow" name="right_elbow"/>
        <position joint="left_shoulder1" name="left_shoulder1"/>
        <position joint="left_shoulder2" name="left_shoulder2"/>
        <position joint="left_elbow" name="left_elbow"/>
        <position joint="left_foot" name="left_foot"/>
        <position joint="right_foot" name="right_foot"/>
    </actuator>
    <sensor>
        <framepos objtype="site" objname="imu" name="position"/>
        <gyro site="imu" name="gyro"/>
        <velocimeter site="imu" name="local_linvel"/>
        <accelerometer site="imu" name="accelerometer"/>
        <framezaxis objtype="site" objname="imu" name="upvector"/>
        <framexaxis objtype="site" objname="imu" name="forwardvector"/>
        <force site="left_foot" name="left_foot_force"/>
        <force site="right_foot" name="right_foot_force"/>
    </sensor>
</mujoco>

<!-- 
add mass to links
change links to be prisms -->

